{
 "cells": [
  {
   "cell_type": "code",
   "execution_count": null,
   "id": "e48435ab",
   "metadata": {},
   "outputs": [
    {
     "name": "stderr",
     "output_type": "stream",
     "text": [
      "ERROR:root:Internal Python error in the inspect module.\n",
      "Below is the traceback from this internal error.\n",
      "\n",
      "ERROR:root:Internal Python error in the inspect module.\n",
      "Below is the traceback from this internal error.\n",
      "\n",
      "ERROR:root:Internal Python error in the inspect module.\n",
      "Below is the traceback from this internal error.\n",
      "\n"
     ]
    },
    {
     "name": "stdout",
     "output_type": "stream",
     "text": [
      "Traceback (most recent call last):\n",
      "  File \"C:\\Users\\user\\anaconda3\\envs\\tf\\lib\\site-packages\\IPython\\core\\interactiveshell.py\", line 3457, in run_code\n",
      "    exec(code_obj, self.user_global_ns, self.user_ns)\n",
      "  File \"C:\\Users\\user\\AppData\\Local\\Temp/ipykernel_13148/4062958137.py\", line 1, in <module>\n",
      "    from tensorflow.keras.models import Sequential\n",
      "  File \"C:\\Users\\user\\anaconda3\\envs\\tf\\lib\\site-packages\\tensorflow\\__init__.py\", line 41, in <module>\n",
      "    from tensorflow.python.tools import module_util as _module_util\n",
      "  File \"C:\\Users\\user\\anaconda3\\envs\\tf\\lib\\site-packages\\tensorflow\\python\\__init__.py\", line 67, in <module>\n",
      "    from tensorflow.python.ops.linalg import linalg\n",
      "  File \"C:\\Users\\user\\anaconda3\\envs\\tf\\lib\\site-packages\\tensorflow\\python\\ops\\linalg\\linalg.py\", line 23, in <module>\n",
      "    from tensorflow.python.ops.linalg import adjoint_registrations as _adjoint_registrations\n",
      "  File \"C:\\Users\\user\\anaconda3\\envs\\tf\\lib\\site-packages\\tensorflow\\python\\ops\\linalg\\adjoint_registrations.py\", line 30, in <module>\n",
      "    from tensorflow.python.ops.linalg import linear_operator_kronecker\n",
      "  File \"<frozen importlib._bootstrap>\", line 1007, in _find_and_load\n",
      "  File \"<frozen importlib._bootstrap>\", line 986, in _find_and_load_unlocked\n",
      "  File \"<frozen importlib._bootstrap>\", line 680, in _load_unlocked\n",
      "  File \"<frozen importlib._bootstrap_external>\", line 846, in exec_module\n",
      "  File \"<frozen importlib._bootstrap_external>\", line 941, in get_code\n",
      "  File \"<frozen importlib._bootstrap_external>\", line 1040, in get_data\n",
      "KeyboardInterrupt\n",
      "\n",
      "During handling of the above exception, another exception occurred:\n",
      "\n",
      "Traceback (most recent call last):\n",
      "  File \"C:\\Users\\user\\anaconda3\\envs\\tf\\lib\\site-packages\\IPython\\core\\interactiveshell.py\", line 2077, in showtraceback\n",
      "    stb = value._render_traceback_()\n",
      "AttributeError: 'KeyboardInterrupt' object has no attribute '_render_traceback_'\n",
      "\n",
      "During handling of the above exception, another exception occurred:\n",
      "\n",
      "Traceback (most recent call last):\n",
      "  File \"C:\\Users\\user\\anaconda3\\envs\\tf\\lib\\site-packages\\IPython\\core\\ultratb.py\", line 1101, in get_records\n",
      "    return _fixed_getinnerframes(etb, number_of_lines_of_context, tb_offset)\n",
      "  File \"C:\\Users\\user\\anaconda3\\envs\\tf\\lib\\site-packages\\IPython\\core\\ultratb.py\", line 248, in wrapped\n",
      "    return f(*args, **kwargs)\n",
      "  File \"C:\\Users\\user\\anaconda3\\envs\\tf\\lib\\site-packages\\IPython\\core\\ultratb.py\", line 281, in _fixed_getinnerframes\n",
      "    records = fix_frame_records_filenames(inspect.getinnerframes(etb, context))\n",
      "  File \"C:\\Users\\user\\anaconda3\\envs\\tf\\lib\\inspect.py\", line 1541, in getinnerframes\n",
      "    frameinfo = (tb.tb_frame,) + getframeinfo(tb, context)\n",
      "  File \"C:\\Users\\user\\anaconda3\\envs\\tf\\lib\\inspect.py\", line 1499, in getframeinfo\n",
      "    filename = getsourcefile(frame) or getfile(frame)\n",
      "  File \"C:\\Users\\user\\anaconda3\\envs\\tf\\lib\\inspect.py\", line 709, in getsourcefile\n",
      "    if getattr(getmodule(object, filename), '__loader__', None) is not None:\n",
      "  File \"C:\\Users\\user\\anaconda3\\envs\\tf\\lib\\inspect.py\", line 752, in getmodule\n",
      "    f = getabsfile(module)\n",
      "  File \"C:\\Users\\user\\anaconda3\\envs\\tf\\lib\\inspect.py\", line 721, in getabsfile\n",
      "    _filename = getsourcefile(object) or getfile(object)\n",
      "  File \"C:\\Users\\user\\anaconda3\\envs\\tf\\lib\\inspect.py\", line 706, in getsourcefile\n",
      "    if os.path.exists(filename):\n",
      "  File \"C:\\Users\\user\\anaconda3\\envs\\tf\\lib\\genericpath.py\", line 19, in exists\n",
      "    os.stat(path)\n",
      "KeyboardInterrupt\n",
      "\n",
      "During handling of the above exception, another exception occurred:\n",
      "\n",
      "Traceback (most recent call last):\n",
      "  File \"C:\\Users\\user\\anaconda3\\envs\\tf\\lib\\site-packages\\IPython\\core\\interactiveshell.py\", line 2079, in showtraceback\n",
      "    stb = self.InteractiveTB.structured_traceback(etype,\n",
      "  File \"C:\\Users\\user\\anaconda3\\envs\\tf\\lib\\site-packages\\IPython\\core\\ultratb.py\", line 1367, in structured_traceback\n",
      "    return FormattedTB.structured_traceback(\n",
      "  File \"C:\\Users\\user\\anaconda3\\envs\\tf\\lib\\site-packages\\IPython\\core\\ultratb.py\", line 1267, in structured_traceback\n",
      "    return VerboseTB.structured_traceback(\n",
      "  File \"C:\\Users\\user\\anaconda3\\envs\\tf\\lib\\site-packages\\IPython\\core\\ultratb.py\", line 1124, in structured_traceback\n",
      "    formatted_exception = self.format_exception_as_a_whole(etype, evalue, etb, number_of_lines_of_context,\n",
      "  File \"C:\\Users\\user\\anaconda3\\envs\\tf\\lib\\site-packages\\IPython\\core\\ultratb.py\", line 1079, in format_exception_as_a_whole\n",
      "    records = self.get_records(etb, number_of_lines_of_context, tb_offset)\n",
      "  File \"C:\\Users\\user\\anaconda3\\envs\\tf\\lib\\site-packages\\IPython\\core\\ultratb.py\", line 1116, in get_records\n",
      "    traceback.print_exc(file=self.ostream)\n",
      "  File \"C:\\Users\\user\\anaconda3\\envs\\tf\\lib\\traceback.py\", line 163, in print_exc\n",
      "    print_exception(*sys.exc_info(), limit=limit, file=file, chain=chain)\n",
      "  File \"C:\\Users\\user\\anaconda3\\envs\\tf\\lib\\traceback.py\", line 103, in print_exception\n",
      "    for line in TracebackException(\n",
      "  File \"C:\\Users\\user\\anaconda3\\envs\\tf\\lib\\traceback.py\", line 533, in __init__\n",
      "    self._load_lines()\n",
      "  File \"C:\\Users\\user\\anaconda3\\envs\\tf\\lib\\traceback.py\", line 545, in _load_lines\n",
      "    self.__context__._load_lines()\n",
      "  File \"C:\\Users\\user\\anaconda3\\envs\\tf\\lib\\traceback.py\", line 545, in _load_lines\n",
      "    self.__context__._load_lines()\n",
      "  File \"C:\\Users\\user\\anaconda3\\envs\\tf\\lib\\traceback.py\", line 543, in _load_lines\n",
      "    frame.line\n",
      "  File \"C:\\Users\\user\\anaconda3\\envs\\tf\\lib\\traceback.py\", line 288, in line\n",
      "    self._line = linecache.getline(self.filename, self.lineno).strip()\n",
      "  File \"C:\\Users\\user\\anaconda3\\envs\\tf\\lib\\linecache.py\", line 30, in getline\n",
      "    lines = getlines(filename, module_globals)\n",
      "  File \"C:\\Users\\user\\anaconda3\\envs\\tf\\lib\\linecache.py\", line 46, in getlines\n",
      "    return updatecache(filename, module_globals)\n",
      "  File \"C:\\Users\\user\\anaconda3\\envs\\tf\\lib\\linecache.py\", line 136, in updatecache\n",
      "    with tokenize.open(fullname) as fp:\n",
      "  File \"C:\\Users\\user\\anaconda3\\envs\\tf\\lib\\tokenize.py\", line 394, in open\n",
      "    encoding, lines = detect_encoding(buffer.readline)\n",
      "  File \"C:\\Users\\user\\anaconda3\\envs\\tf\\lib\\tokenize.py\", line 363, in detect_encoding\n",
      "    first = read_or_stop()\n",
      "  File \"C:\\Users\\user\\anaconda3\\envs\\tf\\lib\\tokenize.py\", line 321, in read_or_stop\n",
      "    return readline()\n",
      "KeyboardInterrupt\n",
      "\n",
      "During handling of the above exception, another exception occurred:\n",
      "\n",
      "Traceback (most recent call last):\n",
      "  File \"C:\\Users\\user\\anaconda3\\envs\\tf\\lib\\site-packages\\IPython\\core\\interactiveshell.py\", line 3377, in run_ast_nodes\n",
      "    if (await self.run_code(code, result,  async_=asy)):\n",
      "  File \"C:\\Users\\user\\anaconda3\\envs\\tf\\lib\\site-packages\\IPython\\core\\interactiveshell.py\", line 3474, in run_code\n",
      "    self.showtraceback(running_compiled_code=True)\n",
      "  File \"C:\\Users\\user\\anaconda3\\envs\\tf\\lib\\site-packages\\IPython\\core\\interactiveshell.py\", line 2092, in showtraceback\n",
      "    print('\\n' + self.get_exception_only(), file=sys.stderr)\n",
      "  File \"C:\\Users\\user\\anaconda3\\envs\\tf\\lib\\site-packages\\IPython\\core\\interactiveshell.py\", line 2037, in get_exception_only\n",
      "    msg = traceback.format_exception_only(etype, value)\n",
      "  File \"C:\\Users\\user\\anaconda3\\envs\\tf\\lib\\traceback.py\", line 140, in format_exception_only\n",
      "    return list(TracebackException(etype, value, None).format_exception_only())\n",
      "  File \"C:\\Users\\user\\anaconda3\\envs\\tf\\lib\\traceback.py\", line 533, in __init__\n",
      "    self._load_lines()\n",
      "  File \"C:\\Users\\user\\anaconda3\\envs\\tf\\lib\\traceback.py\", line 545, in _load_lines\n",
      "    self.__context__._load_lines()\n",
      "  File \"C:\\Users\\user\\anaconda3\\envs\\tf\\lib\\traceback.py\", line 545, in _load_lines\n",
      "    self.__context__._load_lines()\n",
      "  File \"C:\\Users\\user\\anaconda3\\envs\\tf\\lib\\traceback.py\", line 545, in _load_lines\n",
      "    self.__context__._load_lines()\n",
      "  File \"C:\\Users\\user\\anaconda3\\envs\\tf\\lib\\traceback.py\", line 543, in _load_lines\n",
      "    frame.line\n",
      "  File \"C:\\Users\\user\\anaconda3\\envs\\tf\\lib\\traceback.py\", line 288, in line\n",
      "    self._line = linecache.getline(self.filename, self.lineno).strip()\n",
      "  File \"C:\\Users\\user\\anaconda3\\envs\\tf\\lib\\linecache.py\", line 30, in getline\n",
      "    lines = getlines(filename, module_globals)\n",
      "  File \"C:\\Users\\user\\anaconda3\\envs\\tf\\lib\\linecache.py\", line 46, in getlines\n",
      "    return updatecache(filename, module_globals)\n",
      "  File \"C:\\Users\\user\\anaconda3\\envs\\tf\\lib\\linecache.py\", line 136, in updatecache\n",
      "    with tokenize.open(fullname) as fp:\n",
      "  File \"C:\\Users\\user\\anaconda3\\envs\\tf\\lib\\tokenize.py\", line 394, in open\n",
      "    encoding, lines = detect_encoding(buffer.readline)\n",
      "  File \"C:\\Users\\user\\anaconda3\\envs\\tf\\lib\\tokenize.py\", line 363, in detect_encoding\n",
      "    first = read_or_stop()\n",
      "  File \"C:\\Users\\user\\anaconda3\\envs\\tf\\lib\\tokenize.py\", line 321, in read_or_stop\n",
      "    return readline()\n",
      "KeyboardInterrupt\n",
      "\n",
      "During handling of the above exception, another exception occurred:\n",
      "\n",
      "Traceback (most recent call last):\n",
      "  File \"C:\\Users\\user\\anaconda3\\envs\\tf\\lib\\site-packages\\IPython\\core\\interactiveshell.py\", line 2077, in showtraceback\n",
      "    stb = value._render_traceback_()\n",
      "AttributeError: 'KeyboardInterrupt' object has no attribute '_render_traceback_'\n",
      "\n",
      "During handling of the above exception, another exception occurred:\n",
      "\n",
      "Traceback (most recent call last):\n",
      "  File \"C:\\Users\\user\\anaconda3\\envs\\tf\\lib\\site-packages\\IPython\\core\\ultratb.py\", line 1101, in get_records\n",
      "    return _fixed_getinnerframes(etb, number_of_lines_of_context, tb_offset)\n",
      "  File \"C:\\Users\\user\\anaconda3\\envs\\tf\\lib\\site-packages\\IPython\\core\\ultratb.py\", line 248, in wrapped\n",
      "    return f(*args, **kwargs)\n",
      "  File \"C:\\Users\\user\\anaconda3\\envs\\tf\\lib\\site-packages\\IPython\\core\\ultratb.py\", line 281, in _fixed_getinnerframes\n",
      "    records = fix_frame_records_filenames(inspect.getinnerframes(etb, context))\n",
      "  File \"C:\\Users\\user\\anaconda3\\envs\\tf\\lib\\inspect.py\", line 1541, in getinnerframes\n",
      "    frameinfo = (tb.tb_frame,) + getframeinfo(tb, context)\n",
      "  File \"C:\\Users\\user\\anaconda3\\envs\\tf\\lib\\inspect.py\", line 1503, in getframeinfo\n",
      "    lines, lnum = findsource(frame)\n",
      "  File \"C:\\Users\\user\\anaconda3\\envs\\tf\\lib\\site-packages\\IPython\\core\\ultratb.py\", line 182, in findsource\n",
      "    lines = linecache.getlines(file, globals_dict)\n",
      "  File \"C:\\Users\\user\\anaconda3\\envs\\tf\\lib\\linecache.py\", line 46, in getlines\n",
      "    return updatecache(filename, module_globals)\n",
      "  File \"C:\\Users\\user\\anaconda3\\envs\\tf\\lib\\linecache.py\", line 136, in updatecache\n",
      "    with tokenize.open(fullname) as fp:\n",
      "  File \"C:\\Users\\user\\anaconda3\\envs\\tf\\lib\\tokenize.py\", line 394, in open\n",
      "    encoding, lines = detect_encoding(buffer.readline)\n",
      "  File \"C:\\Users\\user\\anaconda3\\envs\\tf\\lib\\tokenize.py\", line 363, in detect_encoding\n",
      "    first = read_or_stop()\n",
      "  File \"C:\\Users\\user\\anaconda3\\envs\\tf\\lib\\tokenize.py\", line 321, in read_or_stop\n",
      "    return readline()\n",
      "KeyboardInterrupt\n",
      "Traceback (most recent call last):\n",
      "  File \"C:\\Users\\user\\anaconda3\\envs\\tf\\lib\\site-packages\\IPython\\core\\interactiveshell.py\", line 3457, in run_code\n",
      "    exec(code_obj, self.user_global_ns, self.user_ns)\n",
      "  File \"C:\\Users\\user\\AppData\\Local\\Temp/ipykernel_13148/4062958137.py\", line 1, in <module>\n",
      "    from tensorflow.keras.models import Sequential\n",
      "  File \"C:\\Users\\user\\anaconda3\\envs\\tf\\lib\\site-packages\\tensorflow\\__init__.py\", line 41, in <module>\n",
      "    from tensorflow.python.tools import module_util as _module_util\n",
      "  File \"C:\\Users\\user\\anaconda3\\envs\\tf\\lib\\site-packages\\tensorflow\\python\\__init__.py\", line 67, in <module>\n",
      "    from tensorflow.python.ops.linalg import linalg\n",
      "  File \"C:\\Users\\user\\anaconda3\\envs\\tf\\lib\\site-packages\\tensorflow\\python\\ops\\linalg\\linalg.py\", line 23, in <module>\n",
      "    from tensorflow.python.ops.linalg import adjoint_registrations as _adjoint_registrations\n",
      "  File \"C:\\Users\\user\\anaconda3\\envs\\tf\\lib\\site-packages\\tensorflow\\python\\ops\\linalg\\adjoint_registrations.py\", line 30, in <module>\n",
      "    from tensorflow.python.ops.linalg import linear_operator_kronecker\n",
      "  File \"<frozen importlib._bootstrap>\", line 1007, in _find_and_load\n",
      "  File \"<frozen importlib._bootstrap>\", line 986, in _find_and_load_unlocked\n",
      "  File \"<frozen importlib._bootstrap>\", line 680, in _load_unlocked\n",
      "  File \"<frozen importlib._bootstrap_external>\", line 846, in exec_module\n",
      "  File \"<frozen importlib._bootstrap_external>\", line 941, in get_code\n",
      "  File \"<frozen importlib._bootstrap_external>\", line 1040, in get_data\n",
      "KeyboardInterrupt\n",
      "\n",
      "During handling of the above exception, another exception occurred:\n",
      "\n",
      "Traceback (most recent call last):\n",
      "  File \"C:\\Users\\user\\anaconda3\\envs\\tf\\lib\\site-packages\\IPython\\core\\interactiveshell.py\", line 2077, in showtraceback\n",
      "    stb = value._render_traceback_()\n",
      "AttributeError: 'KeyboardInterrupt' object has no attribute '_render_traceback_'\n",
      "\n",
      "During handling of the above exception, another exception occurred:\n",
      "\n",
      "Traceback (most recent call last):\n",
      "  File \"C:\\Users\\user\\anaconda3\\envs\\tf\\lib\\site-packages\\IPython\\core\\ultratb.py\", line 1101, in get_records\n",
      "    return _fixed_getinnerframes(etb, number_of_lines_of_context, tb_offset)\n",
      "  File \"C:\\Users\\user\\anaconda3\\envs\\tf\\lib\\site-packages\\IPython\\core\\ultratb.py\", line 248, in wrapped\n",
      "    return f(*args, **kwargs)\n",
      "  File \"C:\\Users\\user\\anaconda3\\envs\\tf\\lib\\site-packages\\IPython\\core\\ultratb.py\", line 281, in _fixed_getinnerframes\n",
      "    records = fix_frame_records_filenames(inspect.getinnerframes(etb, context))\n",
      "  File \"C:\\Users\\user\\anaconda3\\envs\\tf\\lib\\inspect.py\", line 1541, in getinnerframes\n",
      "    frameinfo = (tb.tb_frame,) + getframeinfo(tb, context)\n",
      "  File \"C:\\Users\\user\\anaconda3\\envs\\tf\\lib\\inspect.py\", line 1499, in getframeinfo\n",
      "    filename = getsourcefile(frame) or getfile(frame)\n",
      "  File \"C:\\Users\\user\\anaconda3\\envs\\tf\\lib\\inspect.py\", line 709, in getsourcefile\n",
      "    if getattr(getmodule(object, filename), '__loader__', None) is not None:\n",
      "  File \"C:\\Users\\user\\anaconda3\\envs\\tf\\lib\\inspect.py\", line 752, in getmodule\n",
      "    f = getabsfile(module)\n",
      "  File \"C:\\Users\\user\\anaconda3\\envs\\tf\\lib\\inspect.py\", line 721, in getabsfile\n",
      "    _filename = getsourcefile(object) or getfile(object)\n",
      "  File \"C:\\Users\\user\\anaconda3\\envs\\tf\\lib\\inspect.py\", line 706, in getsourcefile\n",
      "    if os.path.exists(filename):\n",
      "  File \"C:\\Users\\user\\anaconda3\\envs\\tf\\lib\\genericpath.py\", line 19, in exists\n",
      "    os.stat(path)\n",
      "KeyboardInterrupt\n",
      "\n",
      "During handling of the above exception, another exception occurred:\n",
      "\n",
      "Traceback (most recent call last):\n",
      "  File \"C:\\Users\\user\\anaconda3\\envs\\tf\\lib\\site-packages\\IPython\\core\\interactiveshell.py\", line 2079, in showtraceback\n",
      "    stb = self.InteractiveTB.structured_traceback(etype,\n",
      "  File \"C:\\Users\\user\\anaconda3\\envs\\tf\\lib\\site-packages\\IPython\\core\\ultratb.py\", line 1367, in structured_traceback\n",
      "    return FormattedTB.structured_traceback(\n",
      "  File \"C:\\Users\\user\\anaconda3\\envs\\tf\\lib\\site-packages\\IPython\\core\\ultratb.py\", line 1267, in structured_traceback\n",
      "    return VerboseTB.structured_traceback(\n",
      "  File \"C:\\Users\\user\\anaconda3\\envs\\tf\\lib\\site-packages\\IPython\\core\\ultratb.py\", line 1124, in structured_traceback\n",
      "    formatted_exception = self.format_exception_as_a_whole(etype, evalue, etb, number_of_lines_of_context,\n",
      "  File \"C:\\Users\\user\\anaconda3\\envs\\tf\\lib\\site-packages\\IPython\\core\\ultratb.py\", line 1079, in format_exception_as_a_whole\n",
      "    records = self.get_records(etb, number_of_lines_of_context, tb_offset)\n",
      "  File \"C:\\Users\\user\\anaconda3\\envs\\tf\\lib\\site-packages\\IPython\\core\\ultratb.py\", line 1116, in get_records\n",
      "    traceback.print_exc(file=self.ostream)\n",
      "  File \"C:\\Users\\user\\anaconda3\\envs\\tf\\lib\\traceback.py\", line 163, in print_exc\n",
      "    print_exception(*sys.exc_info(), limit=limit, file=file, chain=chain)\n",
      "  File \"C:\\Users\\user\\anaconda3\\envs\\tf\\lib\\traceback.py\", line 103, in print_exception\n",
      "    for line in TracebackException(\n",
      "  File \"C:\\Users\\user\\anaconda3\\envs\\tf\\lib\\traceback.py\", line 533, in __init__\n",
      "    self._load_lines()\n",
      "  File \"C:\\Users\\user\\anaconda3\\envs\\tf\\lib\\traceback.py\", line 545, in _load_lines\n",
      "    self.__context__._load_lines()\n",
      "  File \"C:\\Users\\user\\anaconda3\\envs\\tf\\lib\\traceback.py\", line 545, in _load_lines\n",
      "    self.__context__._load_lines()\n",
      "  File \"C:\\Users\\user\\anaconda3\\envs\\tf\\lib\\traceback.py\", line 543, in _load_lines\n",
      "    frame.line\n",
      "  File \"C:\\Users\\user\\anaconda3\\envs\\tf\\lib\\traceback.py\", line 288, in line\n",
      "    self._line = linecache.getline(self.filename, self.lineno).strip()\n",
      "  File \"C:\\Users\\user\\anaconda3\\envs\\tf\\lib\\linecache.py\", line 30, in getline\n",
      "    lines = getlines(filename, module_globals)\n",
      "  File \"C:\\Users\\user\\anaconda3\\envs\\tf\\lib\\linecache.py\", line 46, in getlines\n",
      "    return updatecache(filename, module_globals)\n",
      "  File \"C:\\Users\\user\\anaconda3\\envs\\tf\\lib\\linecache.py\", line 136, in updatecache\n",
      "    with tokenize.open(fullname) as fp:\n",
      "  File \"C:\\Users\\user\\anaconda3\\envs\\tf\\lib\\tokenize.py\", line 394, in open\n",
      "    encoding, lines = detect_encoding(buffer.readline)\n",
      "  File \"C:\\Users\\user\\anaconda3\\envs\\tf\\lib\\tokenize.py\", line 363, in detect_encoding\n",
      "    first = read_or_stop()\n",
      "  File \"C:\\Users\\user\\anaconda3\\envs\\tf\\lib\\tokenize.py\", line 321, in read_or_stop\n",
      "    return readline()\n",
      "KeyboardInterrupt\n",
      "\n",
      "During handling of the above exception, another exception occurred:\n",
      "\n",
      "Traceback (most recent call last):\n",
      "  File \"C:\\Users\\user\\anaconda3\\envs\\tf\\lib\\site-packages\\IPython\\core\\interactiveshell.py\", line 3377, in run_ast_nodes\n",
      "    if (await self.run_code(code, result,  async_=asy)):\n",
      "  File \"C:\\Users\\user\\anaconda3\\envs\\tf\\lib\\site-packages\\IPython\\core\\interactiveshell.py\", line 3474, in run_code\n",
      "    self.showtraceback(running_compiled_code=True)\n",
      "  File \"C:\\Users\\user\\anaconda3\\envs\\tf\\lib\\site-packages\\IPython\\core\\interactiveshell.py\", line 2092, in showtraceback\n",
      "    print('\\n' + self.get_exception_only(), file=sys.stderr)\n",
      "  File \"C:\\Users\\user\\anaconda3\\envs\\tf\\lib\\site-packages\\IPython\\core\\interactiveshell.py\", line 2037, in get_exception_only\n",
      "    msg = traceback.format_exception_only(etype, value)\n",
      "  File \"C:\\Users\\user\\anaconda3\\envs\\tf\\lib\\traceback.py\", line 140, in format_exception_only\n",
      "    return list(TracebackException(etype, value, None).format_exception_only())\n",
      "  File \"C:\\Users\\user\\anaconda3\\envs\\tf\\lib\\traceback.py\", line 533, in __init__\n",
      "    self._load_lines()\n",
      "  File \"C:\\Users\\user\\anaconda3\\envs\\tf\\lib\\traceback.py\", line 545, in _load_lines\n",
      "    self.__context__._load_lines()\n",
      "  File \"C:\\Users\\user\\anaconda3\\envs\\tf\\lib\\traceback.py\", line 545, in _load_lines\n",
      "    self.__context__._load_lines()\n",
      "  File \"C:\\Users\\user\\anaconda3\\envs\\tf\\lib\\traceback.py\", line 545, in _load_lines\n",
      "    self.__context__._load_lines()\n",
      "  File \"C:\\Users\\user\\anaconda3\\envs\\tf\\lib\\traceback.py\", line 543, in _load_lines\n",
      "    frame.line\n",
      "  File \"C:\\Users\\user\\anaconda3\\envs\\tf\\lib\\traceback.py\", line 288, in line\n",
      "    self._line = linecache.getline(self.filename, self.lineno).strip()\n",
      "  File \"C:\\Users\\user\\anaconda3\\envs\\tf\\lib\\linecache.py\", line 30, in getline\n",
      "    lines = getlines(filename, module_globals)\n",
      "  File \"C:\\Users\\user\\anaconda3\\envs\\tf\\lib\\linecache.py\", line 46, in getlines\n",
      "    return updatecache(filename, module_globals)\n",
      "  File \"C:\\Users\\user\\anaconda3\\envs\\tf\\lib\\linecache.py\", line 136, in updatecache\n",
      "    with tokenize.open(fullname) as fp:\n",
      "  File \"C:\\Users\\user\\anaconda3\\envs\\tf\\lib\\tokenize.py\", line 394, in open\n",
      "    encoding, lines = detect_encoding(buffer.readline)\n",
      "  File \"C:\\Users\\user\\anaconda3\\envs\\tf\\lib\\tokenize.py\", line 363, in detect_encoding\n",
      "    first = read_or_stop()\n",
      "  File \"C:\\Users\\user\\anaconda3\\envs\\tf\\lib\\tokenize.py\", line 321, in read_or_stop\n",
      "    return readline()\n",
      "KeyboardInterrupt\n",
      "\n",
      "During handling of the above exception, another exception occurred:\n",
      "\n",
      "Traceback (most recent call last):\n",
      "  File \"C:\\Users\\user\\anaconda3\\envs\\tf\\lib\\site-packages\\IPython\\core\\interactiveshell.py\", line 2077, in showtraceback\n",
      "    stb = value._render_traceback_()\n",
      "AttributeError: 'KeyboardInterrupt' object has no attribute '_render_traceback_'\n",
      "\n",
      "During handling of the above exception, another exception occurred:\n",
      "\n",
      "Traceback (most recent call last):\n",
      "  File \"C:\\Users\\user\\anaconda3\\envs\\tf\\lib\\site-packages\\IPython\\core\\interactiveshell.py\", line 2960, in _run_cell\n",
      "    return runner(coro)\n",
      "  File \"C:\\Users\\user\\anaconda3\\envs\\tf\\lib\\site-packages\\IPython\\core\\async_helpers.py\", line 78, in _pseudo_sync_runner\n",
      "    coro.send(None)\n",
      "  File \"C:\\Users\\user\\anaconda3\\envs\\tf\\lib\\site-packages\\IPython\\core\\interactiveshell.py\", line 3185, in run_cell_async\n",
      "    has_raised = await self.run_ast_nodes(code_ast.body, cell_name,\n",
      "  File \"C:\\Users\\user\\anaconda3\\envs\\tf\\lib\\site-packages\\IPython\\core\\interactiveshell.py\", line 3396, in run_ast_nodes\n",
      "    self.showtraceback()\n",
      "  File \"C:\\Users\\user\\anaconda3\\envs\\tf\\lib\\site-packages\\IPython\\core\\interactiveshell.py\", line 2079, in showtraceback\n",
      "    stb = self.InteractiveTB.structured_traceback(etype,\n",
      "  File \"C:\\Users\\user\\anaconda3\\envs\\tf\\lib\\site-packages\\IPython\\core\\ultratb.py\", line 1367, in structured_traceback\n",
      "    return FormattedTB.structured_traceback(\n",
      "  File \"C:\\Users\\user\\anaconda3\\envs\\tf\\lib\\site-packages\\IPython\\core\\ultratb.py\", line 1267, in structured_traceback\n",
      "    return VerboseTB.structured_traceback(\n",
      "  File \"C:\\Users\\user\\anaconda3\\envs\\tf\\lib\\site-packages\\IPython\\core\\ultratb.py\", line 1124, in structured_traceback\n",
      "    formatted_exception = self.format_exception_as_a_whole(etype, evalue, etb, number_of_lines_of_context,\n",
      "  File \"C:\\Users\\user\\anaconda3\\envs\\tf\\lib\\site-packages\\IPython\\core\\ultratb.py\", line 1082, in format_exception_as_a_whole\n",
      "    last_unique, recursion_repeat = find_recursion(orig_etype, evalue, records)\n",
      "  File \"C:\\Users\\user\\anaconda3\\envs\\tf\\lib\\site-packages\\IPython\\core\\ultratb.py\", line 382, in find_recursion\n",
      "    return len(records), 0\n",
      "TypeError: object of type 'NoneType' has no len()\n",
      "\n",
      "During handling of the above exception, another exception occurred:\n",
      "\n",
      "Traceback (most recent call last):\n",
      "  File \"C:\\Users\\user\\anaconda3\\envs\\tf\\lib\\site-packages\\IPython\\core\\interactiveshell.py\", line 2077, in showtraceback\n",
      "    stb = value._render_traceback_()\n",
      "AttributeError: 'TypeError' object has no attribute '_render_traceback_'\n",
      "\n",
      "During handling of the above exception, another exception occurred:\n",
      "\n",
      "Traceback (most recent call last):\n",
      "  File \"C:\\Users\\user\\anaconda3\\envs\\tf\\lib\\site-packages\\IPython\\core\\ultratb.py\", line 1101, in get_records\n",
      "    return _fixed_getinnerframes(etb, number_of_lines_of_context, tb_offset)\n",
      "  File \"C:\\Users\\user\\anaconda3\\envs\\tf\\lib\\site-packages\\IPython\\core\\ultratb.py\", line 248, in wrapped\n",
      "    return f(*args, **kwargs)\n",
      "  File \"C:\\Users\\user\\anaconda3\\envs\\tf\\lib\\site-packages\\IPython\\core\\ultratb.py\", line 281, in _fixed_getinnerframes\n",
      "    records = fix_frame_records_filenames(inspect.getinnerframes(etb, context))\n",
      "  File \"C:\\Users\\user\\anaconda3\\envs\\tf\\lib\\inspect.py\", line 1541, in getinnerframes\n",
      "    frameinfo = (tb.tb_frame,) + getframeinfo(tb, context)\n",
      "  File \"C:\\Users\\user\\anaconda3\\envs\\tf\\lib\\inspect.py\", line 1503, in getframeinfo\n",
      "    lines, lnum = findsource(frame)\n",
      "  File \"C:\\Users\\user\\anaconda3\\envs\\tf\\lib\\site-packages\\IPython\\core\\ultratb.py\", line 182, in findsource\n",
      "    lines = linecache.getlines(file, globals_dict)\n",
      "  File \"C:\\Users\\user\\anaconda3\\envs\\tf\\lib\\linecache.py\", line 46, in getlines\n",
      "    return updatecache(filename, module_globals)\n",
      "  File \"C:\\Users\\user\\anaconda3\\envs\\tf\\lib\\linecache.py\", line 136, in updatecache\n",
      "    with tokenize.open(fullname) as fp:\n",
      "  File \"C:\\Users\\user\\anaconda3\\envs\\tf\\lib\\tokenize.py\", line 394, in open\n",
      "    encoding, lines = detect_encoding(buffer.readline)\n",
      "  File \"C:\\Users\\user\\anaconda3\\envs\\tf\\lib\\tokenize.py\", line 363, in detect_encoding\n",
      "    first = read_or_stop()\n",
      "  File \"C:\\Users\\user\\anaconda3\\envs\\tf\\lib\\tokenize.py\", line 321, in read_or_stop\n",
      "    return readline()\n",
      "KeyboardInterrupt\n"
     ]
    }
   ],
   "source": [
    "from tensorflow.keras.models import Sequential\n",
    "from tensorflow.keras.layers import Conv2D, ZeroPadding2D, Activation, Input, concatenate\n",
    "from tensorflow.keras.models import Model\n",
    "from tensorflow.keras.layers import BatchNormalization\n",
    "from tensorflow.keras.layers import MaxPooling2D, AveragePooling2D\n",
    "from tensorflow.keras.layers import Concatenate\n",
    "from tensorflow.keras.layers import Lambda, Flatten, Dense\n",
    "from tensorflow.keras.initializers import glorot_uniform\n",
    "from tensorflow.keras.layers import Layer\n",
    "from tensorflow.keras import backend as K\n",
    "K.set_image_data_format('channels_last')\n",
    "import os\n",
    "import numpy as np\n",
    "from numpy import genfromtxt\n",
    "import pandas as pd\n",
    "import tensorflow as tf\n",
    "import PIL\n",
    "\n",
    "%matplotlib inline\n",
    "%load_ext autoreload\n",
    "%autoreload 2"
   ]
  },
  {
   "cell_type": "code",
   "execution_count": null,
   "id": "307fa10b",
   "metadata": {},
   "outputs": [],
   "source": [
    "from tensorflow.keras.models import model_from_json\n",
    "\n",
    "json_file = open('keras-facenet-h5/model.json', 'r')\n",
    "loaded_model_json = json_file.read()\n",
    "json_file.close()\n",
    "model = model_from_json(loaded_model_json)\n",
    "model.load_weights('keras-facenet-h5/model.h5')"
   ]
  },
  {
   "cell_type": "code",
   "execution_count": 17,
   "id": "ec6fd954",
   "metadata": {},
   "outputs": [
    {
     "data": {
      "text/plain": [
       "'2.6.0'"
      ]
     },
     "execution_count": 17,
     "metadata": {},
     "output_type": "execute_result"
    }
   ],
   "source": [
    "tf.__version__"
   ]
  },
  {
   "cell_type": "code",
   "execution_count": null,
   "id": "b68aeaa9",
   "metadata": {},
   "outputs": [],
   "source": [
    "def triplet_loss(y_true, y_pred, alpha=0.2):\n",
    "    "
   ]
  }
 ],
 "metadata": {
  "kernelspec": {
   "display_name": "Python 3 (ipykernel)",
   "language": "python",
   "name": "python3"
  },
  "language_info": {
   "codemirror_mode": {
    "name": "ipython",
    "version": 3
   },
   "file_extension": ".py",
   "mimetype": "text/x-python",
   "name": "python",
   "nbconvert_exporter": "python",
   "pygments_lexer": "ipython3",
   "version": "3.9.7"
  }
 },
 "nbformat": 4,
 "nbformat_minor": 5
}
